Workbook

Sheet MS PRODUCTION LOG
A1: Date | B1: SQF No | C1: Batch No | D1: MS No | E1: Qty (Nos) | F1: Wt/Pc (Kg) | G1: Total Wt (Kg) | H1: In Time | I1: Out Time | J1: Gap/Loss (min) | K1: Reason of Gap | L1: Charge Wt Loss | M1: Reason of Loss | N1: Remarks | O1: Data Check | P1: Unique Batch (auto - don't edit)
A2: 46266 | B2: 1 | C2: 26H110 | D2: MS 32009 | E2: 260 | F2: 3.04 | G2: 790.4 | H2: 0.40763889 | I2: 0.73611111 | P2: =IF($C2="","",IF(COUNTIF($C$2:$C2,$C2)=1,1,0))
A3: 46266 | B3: 1 | C3: 26I554 | D3: MS 22018 | E3: 34 | F3: 8.4 | G3: 285.6 | H3: 0.71458333 | I3: 0.25 | P3: =IF($C3="","",IF(COUNTIF($C$2:$C3,$C3)=1,1,0))
A4: 46266 | B4: 1 | C4: 26I557 | D4: MS 9064 | E4: 150 | F4: 6.92 | G4: 1038 | H4: 0.22430556 | I4: 0.75138889 | P4: =IF($C4="","",IF(COUNTIF($C$2:$C4,$C4)=1,1,0))
A5: 46266 | B5: 2 | C5: 26I02 | D5: MS 32009 | E5: 260 | F5: 3.04 | G5: 790.4 | H5: 0.46944444 | I5: 0.82083333 | P5: =IF($C5="","",IF(COUNTIF($C$2:$C5,$C5)=1,1,0))
A6: 46266 | B6: 2 | C6: 26I03 | D6: MS 32009 | E6: 260 | F6: 3.04 | G6: 790.4 | H6: 0.79513889 | I6: 0.14583333 | P6: =IF($C6="","",IF(COUNTIF($C$2:$C6,$C6)=1,1,0))
A7: 46266 | B7: 2 | C7: 26I01 | D7: MS 32012 | E7: 450 | F7: 2.1 | G7: 945 | H7: 0.11805556 | I7: 0.47222222 | P7: =IF($C7="","",IF(COUNTIF($C$2:$C7,$C7)=1,1,0))
A8: 46266 | B8: 3 | C8: 26I552 | D8: B/G 2024 | E8: 65 | F8: 16.28 | G8: 1058.2 | H8: 0.37291667 | I8: 0.80902778 | P8: =IF($C8="","",IF(COUNTIF($C$2:$C8,$C8)=1,1,0))
A9: 46266 | B9: 3 | C9: 26I556 | D9: B/G 26010 | E9: 56 | F9: 18.62 | G9: 1042.72 | H9: 0.78263889 | I9: 0.23263889 | P9: =IF($C9="","",IF(COUNTIF($C$2:$C9,$C9)=1,1,0))
A10: 46266 | B10: 3 | C10: 26I558 | D10: B/G 2066 | E10: 94 | F10: 10.08 | G10: 947.52 | H10: 0.20694444 | I10: 0.73263889 | P10: =IF($C10="","",IF(COUNTIF($C$2:$C10,$C10)=1,1,0))
A11: 46266 | B11: 4 | C11: 26I551 | D11: P0003 | E11: 150 | F11: 7 | G11: 1050 | H11: 0.56458333 | I11: 0.93402778 | P11: =IF($C11="","",IF(COUNTIF($C$2:$C11,$C11)=1,1,0))
A12: 46266 | B12: 4 | C12: 26I553 | D12: MS 4411 | E12: 140 | F12: 8.2 | G12: 1148 | H12: 0.90555556 | I12: 0.35555556 | P12: =IF($C12="","",IF(COUNTIF($C$2:$C12,$C12)=1,1,0))
A13: 46267 | B13: 1 | C13: 26I04 | D13: MS 32009 | E13: 260 | F13: 3.04 | G13: 790.4 | H13: 0.72916667 | I13: 0.055555556 | P13: =IF($C13="","",IF(COUNTIF($C$2:$C13,$C13)=1,1,0))
... A70: 46272 | B70: 1 | C70: 26I170 | D70: MS 32009 | E70: 260 | F70: 3.04 | G70: 790.4 | H70: 0.55555556 | I70: 0.88194444 | P70: =IF($C70="","",IF(COUNTIF($C$2:$C70,$C70)=1,1,0))
A71: 46272 | B71: 1 | C71: ZI592 | D71: MS 22018 | E71: 15 | F71: 8.4 | G71: 126 | H71: 0.85486111 | I71: 0.48263889 | O71: Rate/typo check needed | P71: =IF($C71="","",IF(COUNTIF($C$2:$C71,$C71)=1,1,0))
A72: 46272 | B72: 1 | C72: ZI592 | D72: B/G 20002 | E72: 48 | F72: 15.58 | G72: 747.84 | H72: 0.85486111 | I72: 0.48263889 | O72: Rate/typo check needed | P72: =IF($C72="","",IF(COUNTIF($C$2:$C72,$C72)=1,1,0))
A73: 46272 | B73: 2 | C73: 26I593 | D73: MS 9064 | E73: 150 | F73: 6.92 | G73: 1038 | H73: 0.675 | I73: 0.17361111 | P73: =IF($C73="","",IF(COUNTIF($C$2:$C73,$C73)=1,1,0))
A74: 46272 | B74: 2 | C74: 26I19 | D74: MS 32009 | E74: 260 | F74: 3.04 | G74: 790.4 | H74: 0.14444444 | I74: 0.49305556 | P74: =IF($C74="","",IF(COUNTIF($C$2:$C74,$C74)=1,1,0))
A75: 46272 | B75: 3 | C75: 26I589 | D75: MS 4412 | E75: 129 | F75: 8.28 | G75: 1068.12 | H75: 0.32430556 | I75: 0.78958333 | P75: =IF($C75="","",IF(COUNTIF($C$2:$C75,$C75)=1,1,0))
A76: 46272 | B76: 3 | C76: 26I594 | D76: B/G 18000 | E76: 70 | F76: 15.38 | G76: 1076.6 | H76: 0.80208333 | I76: 0.31597222 | P76: =IF($C76="","",IF(COUNTIF($C$2:$C76,$C76)=1,1,0))
A77: 46272 | B77: 4 | C77: 26I591 | D77: MS 4463 | E77: 150 | F77: 7.3 | G77: 1095 | H77: 0.42569444 | I77: 0.90694444 | P77: =IF($C77="","",IF(COUNTIF($C$2:$C77,$C77)=1,1,0))
A78: 46272 | B78: 4 | C78: 26I596 | D78: MS 4412 | E78: 114 | F78: 8.28 | G78: 943.92 | H78: 0.88888889 | I78: 0.32986111 | P78: =IF($C78="","",IF(COUNTIF($C$2:$C78,$C78)=1,1,0))
A79: 46273 | B79: 1 | C79: 26I20 | D79: MS 32009 | E79: 260 | F79: 3.04 | G79: 790.4 | H79: 0.45833333 | I79: 0.79166667 | P79: =IF($C79="","",IF(COUNTIF($C$2:$C79,$C79)=1,1,0))
A80: 46273 | B80: 1 | C80: 26I601 | D80: MS 9064 | E80: 150 | F80: 6.92 | G80: 1038 | H80: 0.75972222 | I80: 0.25 | P80: =IF($C80="","",IF(COUNTIF($C$2:$C80,$C80)=1,1,0))
A81: 46273 | B81: 1 | C81: 26I23 | D81: MS 32009 | E81: 260 | F81: 3.04 | G81: 790.4 | H81: 0.22430556 | I81: 0.55208333 | P81: =IF($C81="","",IF(COUNTIF($C$2:$C81,$C81)=1,1,0))
A82: 46273 | B82: 2 | C82: 26I18 | D82: MS 32012 | E82: 450 | F82: 2.1 | G82: 945 | H82: 0.46805556 | I82: 0.82152778 | P82: =IF($C82="","",IF(COUNTIF($C$2:$C82,$C82)=1,1,0))
A83: 46273 | B83: 2 | C83: 26I21 | D83: MS 32009 | E83: 260 | F83: 3.04 | G83: 790.4 | H83: 0.79375 | I83: 0.14722222 | P83: =IF($C83="","",IF(COUNTIF($C$2:$C83,$C83)=1,1,0))
A84: 46273 | B84: 2 | C84: 26I22 | D84: MS 32012 | E84: 450 | F84: 2.1 | G84: 945 | H84: 0.11944444 | I84: 0.46319444 | P84: =IF($C84="","",IF(COUNTIF($C$2:$C84,$C84)=1,1,0))
A85: 46273 | B85: 3 | C85: 26I595 | D85: MS 21017 | E85: 150 | F85: 5.84 | G85: 876 | H85: 0.29027778 | I85: 0.73611111 | O85: Rate/typo check needed | P85: =IF($C85="","",IF(COUNTIF($C$2:$C85,$C85)=1,1,0))
A86: 46273 | B86: 3 | C86: 26I598 | D86: MS 4463 | E86: 150 | F86: 7.3 | G86: 1095 | H86: 0.70902778 | I86: 0.1875 | P86: =IF($C86="","",IF(COUNTIF($C$2:$C86,$C86)=1,1,0))
A87: 46273 | B87: 3 | C87: ZI602 | D87: B/G 20002 | E87: 67 | F87: 15.58 | G87: 1043.86 | H87: 0.16111111 | I87: 0.73611111 | P87: =IF($C87="","",IF(COUNTIF($C$2:$C87,$C87)=1,1,0))
A88: 46273 | B88: 4 | C88: 26I597 | D88: MS 4529 | E88: 262 | F88: 2.52 | G88: 660.24 | H88: 0.30347222 | I88: 0.69097222 | P88: =IF($C88="","",IF(COUNTIF($C$2:$C88,$C88)=1,1,0))
A89: 46273 | B89: 4 | C89: 26I599 | D89: MS 4435 | E89: 132 | F89: 7.3 | G89: 963.6 | H89: 0.66319444 | I89: 0.14930556 | P89: =IF($C89="","",IF(COUNTIF($C$2:$C89,$C89)=1,1,0))
A90: 46273 | B90: 4 | C90: 26I599 | D90: MS 4463 | E90: 18 | F90: 7.3 | G90: 131.4 | H90: 0.66319444 | I90: 0.14930556 | P90: =IF($C90="","",IF(COUNTIF($C$2:$C90,$C90)=1,1,0))
A91: 46273 | B91: 4 | C91: 26I604 | D91: MS 4463 | E91: 150 | F91: 7.3 | G91: 1095 | H91: 0.12569444 | I91: 0.60069444 | P91: =IF($C91="","",IF(COUNTIF($C$2:$C91,$C91)=1,1,0))
A92: 46274 | B92: 1 | C92: 26I24 | D92: MS 32009 | E92: 260 | F92: 3.04 | G92: 790.4 | H92: 0.52430556 | I92: 0.85763889 | P92: =IF($C92="","",IF(COUNTIF($C$2:$C92,$C92)=1,1,0))
A93: 46274 | B93: 1 | C93: 26I25 | D93: MS 32012 | E93: 450 | F93: 2.1 | G93: 945 | H93: 0.82986111 | I93: 0.17222222 | P93: =IF($C93="","",IF(COUNTIF($C$2:$C93,$C93)=1,1,0))
A94: 46274 | B94: 1 | C94: 26I27 | D94: MS 32009 | E94: 260 | F94: 3.04 | G94: 790.4 | H94: 0.14305556 | I94: 0.46527778 | P94: =IF($C94="","",IF(COUNTIF($C$2:$C94,$C94)=1,1,0))
A95: 46274 | B95: 2 | C95: 26I603 | D95: B/G 18000 | E95: 70 | F95: 15.38 | G95: 1076.6 | H95: 0.43541667 | I95: 0.97777778 | P95: =IF($C95="","",IF(COUNTIF($C$2:$C95,$C95)=1,1,0))
A96: 46274 | B96: 2 | C96: 26I607 | D96: MS 14014 | E96: 32 | F96: 30 | G96: 960 | H96: 0.94791667 | I96: 0.6125 | P96: =IF($C96="","",IF(COUNTIF($C$2:$C96,$C96)=1,1,0))
...

Sheet DWM
A1: MGL UNIT-7 - DWM MATRIX (auto-calculated live from 'MS PRODUCTION LOG' tab - don't type numbers here)
A2: Month Start (change only this cell each month): | G2: 46266
A4: FURNACE | B4: SQF No | C4: Capacity (T) | D4: Month Target (T) | E4: Target MTD (T) | F4: Actual MTD (T) | G4: Util % | H4: 1 | I4: 2 | J4: 3 | K4: 4 | L4: 5 | M4: 6 | N4: 7 | O4: 8 | P4: 9 | Q4: 10 | R4: 11 | S4: 12 | T4: 13 | U4: 14 | V4: 15 | W4: 16 | X4: 17 | Y4: 18 | Z4: 19 | AA4: 20 | AB4: 21 | AC4: 22 | AD4: 23 | AE4: 24 | AF4: 25 | AG4: 26 | AH4: 27 | AI4: 28 | AJ4: 29 | AK4: 30 | AL4: 31
A5: SQF-1 | B5: 1 | C5: 69.75 | D5: 69.75 | E5: 60 | F5: =SUM(H5:AL5) | G5: =IFERROR(F5/E5,0) | H5: =IF(H$4<=DAY(EOMONTH($G$2,0)),IFERROR(SUMIFS('MS PRODUCTION LOG'!$G:$G,'MS PRODUCTION LOG'!$B:$B,$B5,'MS PRODUCTION LOG'!$A:$A,DATE(YEAR($G$2),MONTH($G$2),H$4))/1000,0),"") | I5: =IF(I$4<=DAY(EOMONTH($G$2,0)),IFERROR(SUMIFS('MS PRODUCTION LOG'!$G:$G,'MS PRODUCTION LOG'!$B:$B,$B5,'MS PRODUCTION LOG'!$A:$A,DATE(YEAR($G$2),MONTH($G$2),I$4))/1000,0),"") | J5: =IF(J$4<=DAY(EOMONTH($G$2,0)),IFERROR(SUMIFS('MS PRODUCTION LOG'!$G:$G,'MS PRODUCTION LOG'!$B:$B,$B5,'MS PRODUCTION LOG'!$A:$A,DATE(YEAR($G$2),MONTH($G$2),J$4))/1000,0),"") | K5: =IF(K$4<=DAY(EOMONTH($G$2,0)),IFERROR(SUMIFS('MS PRODUCTION LOG'!$G:$G,'MS PRODUCTION LOG'!$B:$B,$B5,'MS PRODUCTION LOG'!$A:$A,DATE(YEAR($G$2),MONTH($G$2),K$4))/1000,0),"") | L5: =IF(L$4<=DAY(EOMONTH($G$2,0)),IFERROR(SUMIFS('MS PRODUCTION LOG'!$G:$G,'MS PRODUCTION LOG'!$B:$B,$B5,'MS PRODUCTION LOG'!$A:$A,DATE(YEAR($G$2),MONTH($G$2),L$4))/1000,0),"") | M5: =IF(M$4<=DAY(EOMONTH($G$2,0)),IFERROR(SUMIFS('MS PRODUCTION LOG'!$G:$G,'MS PRODUCTION LOG'!$B:$B,$B5,'MS PRODUCTION LOG'!$A:$A,DATE(YEAR($G$2),MONTH($G$2),M$4))/1000,0),"") | N5: =IF(N$4<=DAY(EOMONTH($G$2,0)),IFERROR(SUMIFS('MS PRODUCTION LOG'!$G:$G,'MS PRODUCTION LOG'!$B:$B,$B5,'MS PRODUCTION LOG'!$A:$A,DATE(YEAR($G$2),MONTH($G$2),N$4))/1000,0),"") | O5: =IF(O$4<=DAY(EOMONTH($G$2,0)),IFERROR(SUMIFS('MS PRODUCTION LOG'!$G:$G,'MS PRODUCTION LOG'!$B:$B,$B5,'MS PRODUCTION LOG'!$A:$A,DATE(YEAR($G$2),MONTH($G$2),O$4))/1000,0),"") | ... AL5: =IF(AL$4<=DAY(EOMONTH($G$2,0)),IFERROR(SUMIFS('MS PRODUCTION LOG'!$G:$G,'MS PRODUCTION LOG'!$B:$B,$B5,'MS PRODUCTION LOG'!$A:$A,DATE(YEAR($G$2),MONTH($G$2),AL$4))/1000,0),"")
A6: SQF-2 | B6: 2 | C6: 69.75 | D6: 69.75 | E6: 60 | F6: =SUM(H6:AL6) | G6: =IFERROR(F6/E6,0) | H6: =IF(H$4<=DAY(EOMONTH($G$2,0)),IFERROR(SUMIFS('MS PRODUCTION LOG'!$G:$G,'MS PRODUCTION LOG'!$B:$B,$B6,'MS PRODUCTION LOG'!$A:$A,DATE(YEAR($G$2),MONTH($G$2),H$4))/1000,0),"") | I6: =IF(I$4<=DAY(EOMONTH($G$2,0)),IFERROR(SUMIFS('MS PRODUCTION LOG'!$G:$G,'MS PRODUCTION LOG'!$B:$B,$B6,'MS PRODUCTION LOG'!$A:$A,DATE(YEAR($G$2),MONTH($G$2),I$4))/1000,0),"") | J6: =IF(J$4<=DAY(EOMONTH($G$2,0)),IFERROR(SUMIFS('MS PRODUCTION LOG'!$G:$G,'MS PRODUCTION LOG'!$B:$B,$B6,'MS PRODUCTION LOG'!$A:$A,DATE(YEAR($G$2),MONTH($G$2),J$4))/1000,0),"") | K6: =IF(K$4<=DAY(EOMONTH($G$2,0)),IFERROR(SUMIFS('MS PRODUCTION LOG'!$G:$G,'MS PRODUCTION LOG'!$B:$B,$B6,'MS PRODUCTION LOG'!$A:$A,DATE(YEAR($G$2),MONTH($G$2),K$4))/1000,0),"") | L6: =IF(L$4<=DAY(EOMONTH($G$2,0)),IFERROR(SUMIFS('MS PRODUCTION LOG'!$G:$G,'MS PRODUCTION LOG'!$B:$B,$B6,'MS PRODUCTION LOG'!$A:$A,DATE(YEAR($G$2),MONTH($G$2),L$4))/1000,0),"") | M6: =IF(M$4<=DAY(EOMONTH($G$2,0)),IFERROR(SUMIFS('MS PRODUCTION LOG'!$G:$G,'MS PRODUCTION LOG'!$B:$B,$B6,'MS PRODUCTION LOG'!$A:$A,DATE(YEAR($G$2),MONTH($G$2),M$4))/1000,0),"") | N6: =IF(N$4<=DAY(EOMONTH($G$2,0)),IFERROR(SUMIFS('MS PRODUCTION LOG'!$G:$G,'MS PRODUCTION LOG'!$B:$B,$B6,'MS PRODUCTION LOG'!$A:$A,DATE(YEAR($G$2),MONTH($G$2),N$4))/1000,0),"") | O6: =IF(O$4<=DAY(EOMONTH($G$2,0)),IFERROR(SUMIFS('MS PRODUCTION LOG'!$G:$G,'MS PRODUCTION LOG'!$B:$B,$B6,'MS PRODUCTION LOG'!$A:$A,DATE(YEAR($G$2),MONTH($G$2),O$4))/1000,0),"") | ... AL6: =IF(AL$4<=DAY(EOMONTH($G$2,0)),IFERROR(SUMIFS('MS PRODUCTION LOG'!$G:$G,'MS PRODUCTION LOG'!$B:$B,$B6,'MS PRODUCTION LOG'!$A:$A,DATE(YEAR($G$2),MONTH($G$2),AL$4))/1000,0),"")
A7: SQF-3 | B7: 3 | C7: 69.75 | D7: 69.75 | E7: 60 | F7: =SUM(H7:AL7) | G7: =IFERROR(F7/E7,0) | H7: =IF(H$4<=DAY(EOMONTH($G$2,0)),IFERROR(SUMIFS('MS PRODUCTION LOG'!$G:$G,'MS PRODUCTION LOG'!$B:$B,$B7,'MS PRODUCTION LOG'!$A:$A,DATE(YEAR($G$2),MONTH($G$2),H$4))/1000,0),"") | I7: =IF(I$4<=DAY(EOMONTH($G$2,0)),IFERROR(SUMIFS('MS PRODUCTION LOG'!$G:$G,'MS PRODUCTION LOG'!$B:$B,$B7,'MS PRODUCTION LOG'!$A:$A,DATE(YEAR($G$2),MONTH($G$2),I$4))/1000,0),"") | J7: =IF(J$4<=DAY(EOMONTH($G$2,0)),IFERROR(SUMIFS('MS PRODUCTION LOG'!$G:$G,'MS PRODUCTION LOG'!$B:$B,$B7,'MS PRODUCTION LOG'!$A:$A,DATE(YEAR($G$2),MONTH($G$2),J$4))/1000,0),"") | K7: =IF(K$4<=DAY(EOMONTH($G$2,0)),IFERROR(SUMIFS('MS PRODUCTION LOG'!$G:$G,'MS PRODUCTION LOG'!$B:$B,$B7,'MS PRODUCTION LOG'!$A:$A,DATE(YEAR($G$2),MONTH($G$2),K$4))/1000,0),"") | L7: =IF(L$4<=DAY(EOMONTH($G$2,0)),IFERROR(SUMIFS('MS PRODUCTION LOG'!$G:$G,'MS PRODUCTION LOG'!$B:$B,$B7,'MS PRODUCTION LOG'!$A:$A,DATE(YEAR($G$2),MONTH($G$2),L$4))/1000,0),"") | M7: =IF(M$4<=DAY(EOMONTH($G$2,0)),IFERROR(SUMIFS('MS PRODUCTION LOG'!$G:$G,'MS PRODUCTION LOG'!$B:$B,$B7,'MS PRODUCTION LOG'!$A:$A,DATE(YEAR($G$2),MONTH($G$2),M$4))/1000,0),"") | N7: =IF(N$4<=DAY(EOMONTH($G$2,0)),IFERROR(SUMIFS('MS PRODUCTION LOG'!$G:$G,'MS PRODUCTION LOG'!$B:$B,$B7,'MS PRODUCTION LOG'!$A:$A,DATE(YEAR($G$2),MONTH($G$2),N$4))/1000,0),"") | O7: =IF(O$4<=DAY(EOMONTH($G$2,0)),IFERROR(SUMIFS('MS PRODUCTION LOG'!$G:$G,'MS PRODUCTION LOG'!$B:$B,$B7,'MS PRODUCTION LOG'!$A:$A,DATE(YEAR($G$2),MONTH($G$2),O$4))/1000,0),"") | ... AL7: =IF(AL$4<=DAY(EOMONTH($G$2,0)),IFERROR(SUMIFS('MS PRODUCTION LOG'!$G:$G,'MS PRODUCTION LOG'!$B:$B,$B7,'MS PRODUCTION LOG'!$A:$A,DATE(YEAR($G$2),MONTH($G$2),AL$4))/1000,0),"")
A8: SQF-4 | B8: 4 | C8: 69.75 | D8: 69.75 | E8: 60 | F8: =SUM(H8:AL8) | G8: =IFERROR(F8/E8,0) | H8: =IF(H$4<=DAY(EOMONTH($G$2,0)),IFERROR(SUMIFS('MS PRODUCTION LOG'!$G:$G,'MS PRODUCTION LOG'!$B:$B,$B8,'MS PRODUCTION LOG'!$A:$A,DATE(YEAR($G$2),MONTH($G$2),H$4))/1000,0),"") | I8: =IF(I$4<=DAY(EOMONTH($G$2,0)),IFERROR(SUMIFS('MS PRODUCTION LOG'!$G:$G,'MS PRODUCTION LOG'!$B:$B,$B8,'MS PRODUCTION LOG'!$A:$A,DATE(YEAR($G$2),MONTH($G$2),I$4))/1000,0),"") | J8: =IF(J$4<=DAY(EOMONTH($G$2,0)),IFERROR(SUMIFS('MS PRODUCTION LOG'!$G:$G,'MS PRODUCTION LOG'!$B:$B,$B8,'MS PRODUCTION LOG'!$A:$A,DATE(YEAR($G$2),MONTH($G$2),J$4))/1000,0),"") | K8: =IF(K$4<=DAY(EOMONTH($G$2,0)),IFERROR(SUMIFS('MS PRODUCTION LOG'!$G:$G,'MS PRODUCTION LOG'!$B:$B,$B8,'MS PRODUCTION LOG'!$A:$A,DATE(YEAR($G$2),MONTH($G$2),K$4))/1000,0),"") | L8: =IF(L$4<=DAY(EOMONTH($G$2,0)),IFERROR(SUMIFS('MS PRODUCTION LOG'!$G:$G,'MS PRODUCTION LOG'!$B:$B,$B8,'MS PRODUCTION LOG'!$A:$A,DATE(YEAR($G$2),MONTH($G$2),L$4))/1000,0),"") | M8: =IF(M$4<=DAY(EOMONTH($G$2,0)),IFERROR(SUMIFS('MS PRODUCTION LOG'!$G:$G,'MS PRODUCTION LOG'!$B:$B,$B8,'MS PRODUCTION LOG'!$A:$A,DATE(YEAR($G$2),MONTH($G$2),M$4))/1000,0),"") | N8: =IF(N$4<=DAY(EOMONTH($G$2,0)),IFERROR(SUMIFS('MS PRODUCTION LOG'!$G:$G,'MS PRODUCTION LOG'!$B:$B,$B8,'MS PRODUCTION LOG'!$A:$A,DATE(YEAR($G$2),MONTH($G$2),N$4))/1000,0),"") | O8: =IF(O$4<=DAY(EOMONTH($G$2,0)),IFERROR(SUMIFS('MS PRODUCTION LOG'!$G:$G,'MS PRODUCTION LOG'!$B:$B,$B8,'MS PRODUCTION LOG'!$A:$A,DATE(YEAR($G$2),MONTH($G$2),O$4))/1000,0),"") | ... AL8: =IF(AL$4<=DAY(EOMONTH($G$2,0)),IFERROR(SUMIFS('MS PRODUCTION LOG'!$G:$G,'MS PRODUCTION LOG'!$B:$B,$B8,'MS PRODUCTION LOG'!$A:$A,DATE(YEAR($G$2),MONTH($G$2),AL$4))/1000,0),"")
A9: TOTAL | C9: =SUM(C5:C8) | D9: =SUM(D5:D8) | E9: =SUM(E5:E8) | F9: =SUM(F5:F8) | G9: =IFERROR(F9/E9,0) | H9: =IF(H5="","",SUM(H5:H8)) | I9: =IF(I5="","",SUM(I5:I8)) | J9: =IF(J5="","",SUM(J5:J8)) | K9: =IF(K5="","",SUM(K5:K8)) | L9: =IF(L5="","",SUM(L5:L8)) | M9: =IF(M5="","",SUM(M5:M8)) | N9: =IF(N5="","",SUM(N5:N8)) | O9: =IF(O5="","",SUM(O5:O8)) | ... AL9: =IF(AL5="","",SUM(AL5:AL8))
A10: CUMULATIVE TOTAL | H10: =IF(H9="","",H9) | I10: =IF(I9="",H10,H10+I9) | J10: =IF(J9="",I10,I10+J9) | K10: =IF(K9="",J10,J10+K9) | L10: =IF(L9="",K10,K10+L9) | M10: =IF(M9="",L10,L10+M9) | N10: =IF(N9="",M10,M10+N9) | O10: =IF(O9="",N10,N10+O9) | P10: =IF(P9="",O10,O10+P9) | ... AL10: =IF(AL9="",AK10,AK10+AL9)

Sheet TOTAL ACT
A1: PRODUCTION OF UNIT 7 - AUTO-CALCULATED (from MS PRODUCTION LOG tab - don't type numbers here)
A2: Month Start (change only this cell each month): | E2: 46266
A4: FURNACE | B4: SQF-1 | C4: SQF-2 | D4: SQF-3 | E4: SQF-4 | F4: TOTAL
A5: BATCHES (IN NOS) | B5: =SUMIFS('MS PRODUCTION LOG'!$P:$P,'MS PRODUCTION LOG'!$B:$B,1,'MS PRODUCTION LOG'!$A:$A,">="&$E$2,'MS PRODUCTION LOG'!$A:$A,"<="&EOMONTH($E$2,0)) | C5: =SUMIFS('MS PRODUCTION LOG'!$P:$P,'MS PRODUCTION LOG'!$B:$B,2,'MS PRODUCTION LOG'!$A:$A,">="&$E$2,'MS PRODUCTION LOG'!$A:$A,"<="&EOMONTH($E$2,0)) | D5: =SUMIFS('MS PRODUCTION LOG'!$P:$P,'MS PRODUCTION LOG'!$B:$B,3,'MS PRODUCTION LOG'!$A:$A,">="&$E$2,'MS PRODUCTION LOG'!$A:$A,"<="&EOMONTH($E$2,0)) | E5: =SUMIFS('MS PRODUCTION LOG'!$P:$P,'MS PRODUCTION LOG'!$B:$B,4,'MS PRODUCTION LOG'!$A:$A,">="&$E$2,'MS PRODUCTION LOG'!$A:$A,"<="&EOMONTH($E$2,0)) | F5: =SUM(B5:E5)
A6: TOTAL NUMBER OF PARTS (SQF WISE) | B6: =SUMIFS('MS PRODUCTION LOG'!$E:$E,'MS PRODUCTION LOG'!$B:$B,1,'MS PRODUCTION LOG'!$A:$A,">="&$E$2,'MS PRODUCTION LOG'!$A:$A,"<="&EOMONTH($E$2,0)) | C6: =SUMIFS('MS PRODUCTION LOG'!$E:$E,'MS PRODUCTION LOG'!$B:$B,2,'MS PRODUCTION LOG'!$A:$A,">="&$E$2,'MS PRODUCTION LOG'!$A:$A,"<="&EOMONTH($E$2,0)) | D6: =SUMIFS('MS PRODUCTION LOG'!$E:$E,'MS PRODUCTION LOG'!$B:$B,3,'MS PRODUCTION LOG'!$A:$A,">="&$E$2,'MS PRODUCTION LOG'!$A:$A,"<="&EOMONTH($E$2,0)) | E6: =SUMIFS('MS PRODUCTION LOG'!$E:$E,'MS PRODUCTION LOG'!$B:$B,4,'MS PRODUCTION LOG'!$A:$A,">="&$E$2,'MS PRODUCTION LOG'!$A:$A,"<="&EOMONTH($E$2,0)) | F6: =SUM(B6:E6)
A7: TOTAL WEIGHT (IN KGS) | B7: =SUMIFS('MS PRODUCTION LOG'!$G:$G,'MS PRODUCTION LOG'!$B:$B,1,'MS PRODUCTION LOG'!$A:$A,">="&$E$2,'MS PRODUCTION LOG'!$A:$A,"<="&EOMONTH($E$2,0)) | C7: =SUMIFS('MS PRODUCTION LOG'!$G:$G,'MS PRODUCTION LOG'!$B:$B,2,'MS PRODUCTION LOG'!$A:$A,">="&$E$2,'MS PRODUCTION LOG'!$A:$A,"<="&EOMONTH($E$2,0)) | D7: =SUMIFS('MS PRODUCTION LOG'!$G:$G,'MS PRODUCTION LOG'!$B:$B,3,'MS PRODUCTION LOG'!$A:$A,">="&$E$2,'MS PRODUCTION LOG'!$A:$A,"<="&EOMONTH($E$2,0)) | E7: =SUMIFS('MS PRODUCTION LOG'!$G:$G,'MS PRODUCTION LOG'!$B:$B,4,'MS PRODUCTION LOG'!$A:$A,">="&$E$2,'MS PRODUCTION LOG'!$A:$A,"<="&EOMONTH($E$2,0)) | F7: =SUM(B7:E7)
A9: GRAND WEIGHT (IN KGS) | B9: =F7
A10: GRAND WEIGHT (IN TONS) | B10: =B9/1000
A11: TOTAL BATCHES (IN NOS) | B11: =F5
A12: TOTAL NUMBER OF PARTS | B12: =F6
A14: MAJOR PRODUCTION LOSS'S
A15: TOTAL PRODUCTION IN TON | B15: =B10
A16: NO OF DUMMY LOT PROCEED IN NPD PARTS (fill manually) | B16: NIL
A17: Furnace idle - no load / material not available (fill manually) | B17: 0
A18: Loss due to Furnace Breakdown & PM work (fill manually) | B18: NIL

Sheet TD PRODUCTION
A1: HEAT TREATMENT - U7 (auto-calculated from MS PRODUCTION LOG tab - don't type numbers here)
A2: Date (jo date daalenge, USI din ka live data yahan aa jayega): | D2: =TODAY()
A4: FURNACE NO | B4: TD QTY | C4: MTD QTY | D4: TD TON | E4: MTD TON
A5: SQF - 01 | B5: =SUMIFS('MS PRODUCTION LOG'!$E:$E,'MS PRODUCTION LOG'!$B:$B,1,'MS PRODUCTION LOG'!$A:$A,$D$2) | C5: =SUMIFS('MS PRODUCTION LOG'!$E:$E,'MS PRODUCTION LOG'!$B:$B,1,'MS PRODUCTION LOG'!$A:$A,">="&DATE(YEAR($D$2),MONTH($D$2),1),'MS PRODUCTION LOG'!$A:$A,"<="&$D$2) | D5: =SUMIFS('MS PRODUCTION LOG'!$G:$G,'MS PRODUCTION LOG'!$B:$B,1,'MS PRODUCTION LOG'!$A:$A,$D$2)/1000 | E5: =SUMIFS('MS PRODUCTION LOG'!$G:$G,'MS PRODUCTION LOG'!$B:$B,1,'MS PRODUCTION LOG'!$A:$A,">="&DATE(YEAR($D$2),MONTH($D$2),1),'MS PRODUCTION LOG'!$A:$A,"<="&$D$2)/1000
A6: SQF - 02 | B6: =SUMIFS('MS PRODUCTION LOG'!$E:$E,'MS PRODUCTION LOG'!$B:$B,2,'MS PRODUCTION LOG'!$A:$A,$D$2) | C6: =SUMIFS('MS PRODUCTION LOG'!$E:$E,'MS PRODUCTION LOG'!$B:$B,2,'MS PRODUCTION LOG'!$A:$A,">="&DATE(YEAR($D$2),MONTH($D$2),1),'MS PRODUCTION LOG'!$A:$A,"<="&$D$2) | D6: =SUMIFS('MS PRODUCTION LOG'!$G:$G,'MS PRODUCTION LOG'!$B:$B,2,'MS PRODUCTION LOG'!$A:$A,$D$2)/1000 | E6: =SUMIFS('MS PRODUCTION LOG'!$G:$G,'MS PRODUCTION LOG'!$B:$B,2,'MS PRODUCTION LOG'!$A:$A,">="&DATE(YEAR($D$2),MONTH($D$2),1),'MS PRODUCTION LOG'!$A:$A,"<="&$D$2)/1000
A7: SQF - 03 | B7: =SUMIFS('MS PRODUCTION LOG'!$E:$E,'MS PRODUCTION LOG'!$B:$B,3,'MS PRODUCTION LOG'!$A:$A,$D$2) | C7: =SUMIFS('MS PRODUCTION LOG'!$E:$E,'MS PRODUCTION LOG'!$B:$B,3,'MS PRODUCTION LOG'!$A:$A,">="&DATE(YEAR($D$2),MONTH($D$2),1),'MS PRODUCTION LOG'!$A:$A,"<="&$D$2) | D7: =SUMIFS('MS PRODUCTION LOG'!$G:$G,'MS PRODUCTION LOG'!$B:$B,3,'MS PRODUCTION LOG'!$A:$A,$D$2)/1000 | E7: =SUMIFS('MS PRODUCTION LOG'!$G:$G,'MS PRODUCTION LOG'!$B:$B,3,'MS PRODUCTION LOG'!$A:$A,">="&DATE(YEAR($D$2),MONTH($D$2),1),'MS PRODUCTION LOG'!$A:$A,"<="&$D$2)/1000
A8: SQF - 04 | B8: =SUMIFS('MS PRODUCTION LOG'!$E:$E,'MS PRODUCTION LOG'!$B:$B,4,'MS PRODUCTION LOG'!$A:$A,$D$2) | C8: =SUMIFS('MS PRODUCTION LOG'!$E:$E,'MS PRODUCTION LOG'!$B:$B,4,'MS PRODUCTION LOG'!$A:$A,">="&DATE(YEAR($D$2),MONTH($D$2),1),'MS PRODUCTION LOG'!$A:$A,"<="&$D$2) | D8: =SUMIFS('MS PRODUCTION LOG'!$G:$G,'MS PRODUCTION LOG'!$B:$B,4,'MS PRODUCTION LOG'!$A:$A,$D$2)/1000 | E8: =SUMIFS('MS PRODUCTION LOG'!$G:$G,'MS PRODUCTION LOG'!$B:$B,4,'MS PRODUCTION LOG'!$A:$A,">="&DATE(YEAR($D$2),MONTH($D$2),1),'MS PRODUCTION LOG'!$A:$A,"<="&$D$2)/1000
A9: TOTAL | B9: =SUM(B5:B8) | C9: =SUM(C5:C8) | D9: =SUM(D5:D8) | E9: =SUM(E5:E8)
